{"tag": "function", "depth": 1, "time": 1741668306.820369, "data": {"name": "connect_device", "call_args": {"uri": "ios:///http://127.0.0.1:8100"}, "start_time": 1741668282.4158568, "traceback": "Traceback (most recent call last):\n  File \"/Library/Frameworks/Python.framework/Versions/3.13/lib/python3.13/site-packages/airtest/utils/logwraper.py\", line 134, in wrapper\n    res = f(*args, **kwargs)\n  File \"/Library/Frameworks/Python.framework/Versions/3.13/lib/python3.13/site-packages/airtest/core/api.py\", line 74, in connect_device\n    dev = init_device(platform, uuid, **params)\n  File \"/Library/Frameworks/Python.framework/Versions/3.13/lib/python3.13/site-packages/airtest/core/api.py\", line 42, in init_device\n    dev = cls(uuid, **kwargs)\n  File \"/Library/Frameworks/Python.framework/Versions/3.13/lib/python3.13/site-packages/airtest/core/ios/ios.py\", line 651, in __init__\n    self.driver = wda.USBClient(udid=self.udid, port=8100, wda_bundle_id=self.wda_bundle_id)\n                  ~~~~~~~~~~~~~^^^^^^^^^^^^^^^^^^^^^^^^^^^^^^^^^^^^^^^^^^^^^^^^^^^^^^^^^^^^^\n  File \"/Library/Frameworks/Python.framework/Versions/3.13/lib/python3.13/site-packages/wda/__init__.py\", line 1783, in __init__\n    raise RuntimeError(\"wda xctest launched but check failed\")\nRuntimeError: wda xctest launched but check failed\n", "end_time": 1741668306.8203251}}
